2022-01-05 15:58:56,547 ERROR: Exception on /train [GET] [in /home/daniel/dke/venv/lib/python3.8/site-packages/flask/app.py:1891]
Traceback (most recent call last):
  File "/home/daniel/dke/venv/lib/python3.8/site-packages/flask/app.py", line 2447, in wsgi_app
    response = self.full_dispatch_request()
  File "/home/daniel/dke/venv/lib/python3.8/site-packages/flask/app.py", line 1952, in full_dispatch_request
    rv = self.handle_user_exception(e)
  File "/home/daniel/dke/venv/lib/python3.8/site-packages/flask/app.py", line 1821, in handle_user_exception
    reraise(exc_type, exc_value, tb)
  File "/home/daniel/dke/venv/lib/python3.8/site-packages/flask/_compat.py", line 39, in reraise
    raise value
  File "/home/daniel/dke/venv/lib/python3.8/site-packages/flask/app.py", line 1950, in full_dispatch_request
    rv = self.dispatch_request()
  File "/home/daniel/dke/venv/lib/python3.8/site-packages/flask/app.py", line 1936, in dispatch_request
    return self.view_functions[rule.endpoint](**req.view_args)
  File "/home/daniel/dke/app/routes.py", line 85, in train
    form = TrainForm()
  File "/home/daniel/dke/venv/lib/python3.8/site-packages/wtforms/form.py", line 208, in __call__
    return type.__call__(cls, *args, **kwargs)
  File "/home/daniel/dke/venv/lib/python3.8/site-packages/flask_wtf/form.py", line 73, in __init__
    super().__init__(formdata=formdata, **kwargs)
  File "/home/daniel/dke/venv/lib/python3.8/site-packages/wtforms/form.py", line 280, in __init__
    super().__init__(self._unbound_fields, meta=meta_obj, prefix=prefix)
  File "/home/daniel/dke/venv/lib/python3.8/site-packages/wtforms/form.py", line 48, in __init__
    field = meta.bind_field(self, unbound_field, options)
  File "/home/daniel/dke/venv/lib/python3.8/site-packages/wtforms/meta.py", line 28, in bind_field
    return unbound_field.bind(form=form, **options)
  File "/home/daniel/dke/venv/lib/python3.8/site-packages/wtforms/fields/core.py", line 395, in bind
    return self.field_class(*self.args, **kw)
  File "/home/daniel/dke/venv/lib/python3.8/site-packages/wtforms/fields/list.py", line 52, in __init__
    assert isinstance(
AssertionError: Field must be unbound, not a field class
2022-01-05 17:01:31,803 INFO: Microblog startup [in /home/daniel/dke/app/__init__.py:44]
2022-01-05 17:01:35,216 ERROR: Exception on /train [GET] [in /home/daniel/dke/venv/lib/python3.8/site-packages/flask/app.py:1891]
Traceback (most recent call last):
  File "/home/daniel/dke/venv/lib/python3.8/site-packages/flask/app.py", line 2447, in wsgi_app
    response = self.full_dispatch_request()
  File "/home/daniel/dke/venv/lib/python3.8/site-packages/flask/app.py", line 1952, in full_dispatch_request
    rv = self.handle_user_exception(e)
  File "/home/daniel/dke/venv/lib/python3.8/site-packages/flask/app.py", line 1821, in handle_user_exception
    reraise(exc_type, exc_value, tb)
  File "/home/daniel/dke/venv/lib/python3.8/site-packages/flask/_compat.py", line 39, in reraise
    raise value
  File "/home/daniel/dke/venv/lib/python3.8/site-packages/flask/app.py", line 1950, in full_dispatch_request
    rv = self.dispatch_request()
  File "/home/daniel/dke/venv/lib/python3.8/site-packages/flask/app.py", line 1936, in dispatch_request
    return self.view_functions[rule.endpoint](**req.view_args)
  File "/home/daniel/dke/app/routes.py", line 85, in train
    form = TrainForm()
  File "/home/daniel/dke/venv/lib/python3.8/site-packages/wtforms/form.py", line 208, in __call__
    return type.__call__(cls, *args, **kwargs)
  File "/home/daniel/dke/venv/lib/python3.8/site-packages/flask_wtf/form.py", line 73, in __init__
    super().__init__(formdata=formdata, **kwargs)
  File "/home/daniel/dke/venv/lib/python3.8/site-packages/wtforms/form.py", line 280, in __init__
    super().__init__(self._unbound_fields, meta=meta_obj, prefix=prefix)
  File "/home/daniel/dke/venv/lib/python3.8/site-packages/wtforms/form.py", line 48, in __init__
    field = meta.bind_field(self, unbound_field, options)
  File "/home/daniel/dke/venv/lib/python3.8/site-packages/wtforms/meta.py", line 28, in bind_field
    return unbound_field.bind(form=form, **options)
  File "/home/daniel/dke/venv/lib/python3.8/site-packages/wtforms/fields/core.py", line 395, in bind
    return self.field_class(*self.args, **kw)
  File "/home/daniel/dke/venv/lib/python3.8/site-packages/wtforms/fields/list.py", line 46, in __init__
    super().__init__(label, validators, default=default, **kwargs)
TypeError: __init__() got an unexpected keyword argument 'query_factory'
2022-01-05 17:02:50,196 INFO: Microblog startup [in /home/daniel/dke/app/__init__.py:44]
2022-01-05 17:02:54,448 ERROR: Exception on /train [GET] [in /home/daniel/dke/venv/lib/python3.8/site-packages/flask/app.py:1891]
Traceback (most recent call last):
  File "/home/daniel/dke/venv/lib/python3.8/site-packages/flask/app.py", line 2447, in wsgi_app
    response = self.full_dispatch_request()
  File "/home/daniel/dke/venv/lib/python3.8/site-packages/flask/app.py", line 1952, in full_dispatch_request
    rv = self.handle_user_exception(e)
  File "/home/daniel/dke/venv/lib/python3.8/site-packages/flask/app.py", line 1821, in handle_user_exception
    reraise(exc_type, exc_value, tb)
  File "/home/daniel/dke/venv/lib/python3.8/site-packages/flask/_compat.py", line 39, in reraise
    raise value
  File "/home/daniel/dke/venv/lib/python3.8/site-packages/flask/app.py", line 1950, in full_dispatch_request
    rv = self.dispatch_request()
  File "/home/daniel/dke/venv/lib/python3.8/site-packages/flask/app.py", line 1936, in dispatch_request
    return self.view_functions[rule.endpoint](**req.view_args)
  File "/home/daniel/dke/app/routes.py", line 91, in train
    return render_template('train.html', title='Train', form=form)
  File "/home/daniel/dke/venv/lib/python3.8/site-packages/flask/templating.py", line 137, in render_template
    return _render(
  File "/home/daniel/dke/venv/lib/python3.8/site-packages/flask/templating.py", line 120, in _render
    rv = template.render(context)
  File "/home/daniel/dke/venv/lib/python3.8/site-packages/jinja2/environment.py", line 1090, in render
    self.environment.handle_exception()
  File "/home/daniel/dke/venv/lib/python3.8/site-packages/jinja2/environment.py", line 832, in handle_exception
    reraise(*rewrite_traceback_stack(source=source))
  File "/home/daniel/dke/venv/lib/python3.8/site-packages/jinja2/_compat.py", line 28, in reraise
    raise value.with_traceback(tb)
  File "/home/daniel/dke/app/templates/train.html", line 1, in top-level template code
    {% extends 'base.html' %}
  File "/home/daniel/dke/app/templates/base.html", line 37, in top-level template code
    {% block content %}{% endblock %}
  File "/home/daniel/dke/app/templates/train.html", line 28, in block "content"
    <p>{{ form.submit() }}</p>
jinja2.exceptions.UndefinedError: 'app.forms.TrainForm object' has no attribute 'submit'
2022-01-05 17:03:39,367 INFO: Microblog startup [in /home/daniel/dke/app/__init__.py:44]
