2022-01-18 16:54:59,357 ERROR: Exception on /user/Daniel [GET] [in /home/daniel/dke/venv/lib/python3.8/site-packages/flask/app.py:1891]
Traceback (most recent call last):
  File "/home/daniel/dke/venv/lib/python3.8/site-packages/flask/app.py", line 2447, in wsgi_app
    response = self.full_dispatch_request()
  File "/home/daniel/dke/venv/lib/python3.8/site-packages/flask/app.py", line 1952, in full_dispatch_request
    rv = self.handle_user_exception(e)
  File "/home/daniel/dke/venv/lib/python3.8/site-packages/flask/app.py", line 1821, in handle_user_exception
    reraise(exc_type, exc_value, tb)
  File "/home/daniel/dke/venv/lib/python3.8/site-packages/flask/_compat.py", line 39, in reraise
    raise value
  File "/home/daniel/dke/venv/lib/python3.8/site-packages/flask/app.py", line 1950, in full_dispatch_request
    rv = self.dispatch_request()
  File "/home/daniel/dke/venv/lib/python3.8/site-packages/flask/app.py", line 1936, in dispatch_request
    return self.view_functions[rule.endpoint](**req.view_args)
  File "/home/daniel/dke/venv/lib/python3.8/site-packages/flask_login/utils.py", line 272, in decorated_view
    return func(*args, **kwargs)
  File "/home/daniel/dke/app/routes.py", line 87, in user
    return render_template('user.html', user=user, maintenances=maintenances)
UnboundLocalError: local variable 'maintenances' referenced before assignment
2022-01-18 16:56:01,887 INFO: Microblog startup [in /home/daniel/dke/app/__init__.py:47]
2022-01-18 17:00:13,584 INFO: Microblog startup [in /home/daniel/dke/app/__init__.py:47]
2022-01-18 17:05:22,993 INFO: Microblog startup [in /home/daniel/dke/app/__init__.py:47]
2022-01-18 17:06:35,403 INFO: Microblog startup [in /home/daniel/dke/app/__init__.py:47]
