2022-01-17 15:40:22,631 ERROR: Exception on /maintenance [POST] [in /home/daniel/dke/venv/lib/python3.8/site-packages/flask/app.py:1891]
Traceback (most recent call last):
  File "/home/daniel/dke/venv/lib/python3.8/site-packages/flask/app.py", line 2447, in wsgi_app
    response = self.full_dispatch_request()
  File "/home/daniel/dke/venv/lib/python3.8/site-packages/flask/app.py", line 1952, in full_dispatch_request
    rv = self.handle_user_exception(e)
  File "/home/daniel/dke/venv/lib/python3.8/site-packages/flask/app.py", line 1821, in handle_user_exception
    reraise(exc_type, exc_value, tb)
  File "/home/daniel/dke/venv/lib/python3.8/site-packages/flask/_compat.py", line 39, in reraise
    raise value
  File "/home/daniel/dke/venv/lib/python3.8/site-packages/flask/app.py", line 1950, in full_dispatch_request
    rv = self.dispatch_request()
  File "/home/daniel/dke/venv/lib/python3.8/site-packages/flask/app.py", line 1936, in dispatch_request
    return self.view_functions[rule.endpoint](**req.view_args)
  File "/home/daniel/dke/app/routes.py", line 125, in maintenance
    maintenance = Maintenance(id=form.id.data, user=form.user.data, train=form.train.data, time=form.time.data)
  File "<string>", line 4, in __init__
  File "/home/daniel/dke/venv/lib/python3.8/site-packages/sqlalchemy/orm/state.py", line 480, in _initialize_instance
    manager.dispatch.init_failure(self, args, kwargs)
  File "/home/daniel/dke/venv/lib/python3.8/site-packages/sqlalchemy/util/langhelpers.py", line 70, in __exit__
    compat.raise_(
  File "/home/daniel/dke/venv/lib/python3.8/site-packages/sqlalchemy/util/compat.py", line 207, in raise_
    raise exception
  File "/home/daniel/dke/venv/lib/python3.8/site-packages/sqlalchemy/orm/state.py", line 477, in _initialize_instance
    return manager.original_init(*mixed[1:], **kwargs)
  File "/home/daniel/dke/venv/lib/python3.8/site-packages/sqlalchemy/orm/decl_base.py", line 1154, in _declarative_constructor
    raise TypeError(
TypeError: 'user' is an invalid keyword argument for Maintenance
2022-01-17 15:45:08,643 INFO: Microblog startup [in /home/daniel/dke/app/__init__.py:47]
2022-01-17 15:45:12,004 ERROR: Exception on /maintenance [GET] [in /home/daniel/dke/venv/lib/python3.8/site-packages/flask/app.py:1891]
Traceback (most recent call last):
  File "/home/daniel/dke/venv/lib/python3.8/site-packages/flask/app.py", line 2447, in wsgi_app
    response = self.full_dispatch_request()
  File "/home/daniel/dke/venv/lib/python3.8/site-packages/flask/app.py", line 1952, in full_dispatch_request
    rv = self.handle_user_exception(e)
  File "/home/daniel/dke/venv/lib/python3.8/site-packages/flask/app.py", line 1821, in handle_user_exception
    reraise(exc_type, exc_value, tb)
  File "/home/daniel/dke/venv/lib/python3.8/site-packages/flask/_compat.py", line 39, in reraise
    raise value
  File "/home/daniel/dke/venv/lib/python3.8/site-packages/flask/app.py", line 1950, in full_dispatch_request
    rv = self.dispatch_request()
  File "/home/daniel/dke/venv/lib/python3.8/site-packages/flask/app.py", line 1936, in dispatch_request
    return self.view_functions[rule.endpoint](**req.view_args)
  File "/home/daniel/dke/app/routes.py", line 129, in maintenance
    return render_template('maintenance.html', title='Maintenance', form=form)
  File "/home/daniel/dke/venv/lib/python3.8/site-packages/flask/templating.py", line 137, in render_template
    return _render(
  File "/home/daniel/dke/venv/lib/python3.8/site-packages/flask/templating.py", line 120, in _render
    rv = template.render(context)
  File "/home/daniel/dke/venv/lib/python3.8/site-packages/jinja2/environment.py", line 1090, in render
    self.environment.handle_exception()
  File "/home/daniel/dke/venv/lib/python3.8/site-packages/jinja2/environment.py", line 832, in handle_exception
    reraise(*rewrite_traceback_stack(source=source))
  File "/home/daniel/dke/venv/lib/python3.8/site-packages/jinja2/_compat.py", line 28, in reraise
    raise value.with_traceback(tb)
  File "/home/daniel/dke/app/templates/maintenance.html", line 1, in top-level template code
    {% extends 'base.html' %}
  File "/home/daniel/dke/app/templates/base.html", line 37, in top-level template code
    {% block content %}{% endblock %}
  File "/home/daniel/dke/app/templates/maintenance.html", line 15, in block "content"
    {{ form.user.label }}<br>
  File "/home/daniel/dke/venv/lib/python3.8/site-packages/jinja2/environment.py", line 471, in getattr
    return getattr(obj, attribute)
jinja2.exceptions.UndefinedError: 'app.forms.MaintenanceForm object' has no attribute 'user'
2022-01-17 15:47:10,743 INFO: Microblog startup [in /home/daniel/dke/app/__init__.py:47]
2022-01-17 15:47:25,957 ERROR: Exception on /maintenance [POST] [in /home/daniel/dke/venv/lib/python3.8/site-packages/flask/app.py:1891]
Traceback (most recent call last):
  File "/home/daniel/dke/venv/lib/python3.8/site-packages/flask/app.py", line 2447, in wsgi_app
    response = self.full_dispatch_request()
  File "/home/daniel/dke/venv/lib/python3.8/site-packages/flask/app.py", line 1952, in full_dispatch_request
    rv = self.handle_user_exception(e)
  File "/home/daniel/dke/venv/lib/python3.8/site-packages/flask/app.py", line 1821, in handle_user_exception
    reraise(exc_type, exc_value, tb)
  File "/home/daniel/dke/venv/lib/python3.8/site-packages/flask/_compat.py", line 39, in reraise
    raise value
  File "/home/daniel/dke/venv/lib/python3.8/site-packages/flask/app.py", line 1950, in full_dispatch_request
    rv = self.dispatch_request()
  File "/home/daniel/dke/venv/lib/python3.8/site-packages/flask/app.py", line 1936, in dispatch_request
    return self.view_functions[rule.endpoint](**req.view_args)
  File "/home/daniel/dke/app/routes.py", line 125, in maintenance
    maintenance = Maintenance(id=form.id.data, user=form.user.data, train=form.train.data, time=form.time.data)
AttributeError: 'MaintenanceForm' object has no attribute 'user'
2022-01-17 15:48:10,597 INFO: Microblog startup [in /home/daniel/dke/app/__init__.py:47]
2022-01-17 15:48:22,189 ERROR: Exception on /maintenance [POST] [in /home/daniel/dke/venv/lib/python3.8/site-packages/flask/app.py:1891]
Traceback (most recent call last):
  File "/home/daniel/dke/venv/lib/python3.8/site-packages/flask/app.py", line 2447, in wsgi_app
    response = self.full_dispatch_request()
  File "/home/daniel/dke/venv/lib/python3.8/site-packages/flask/app.py", line 1952, in full_dispatch_request
    rv = self.handle_user_exception(e)
  File "/home/daniel/dke/venv/lib/python3.8/site-packages/flask/app.py", line 1821, in handle_user_exception
    reraise(exc_type, exc_value, tb)
  File "/home/daniel/dke/venv/lib/python3.8/site-packages/flask/_compat.py", line 39, in reraise
    raise value
  File "/home/daniel/dke/venv/lib/python3.8/site-packages/flask/app.py", line 1950, in full_dispatch_request
    rv = self.dispatch_request()
  File "/home/daniel/dke/venv/lib/python3.8/site-packages/flask/app.py", line 1936, in dispatch_request
    return self.view_functions[rule.endpoint](**req.view_args)
  File "/home/daniel/dke/app/routes.py", line 125, in maintenance
    maintenance = Maintenance(id=form.id.data, user=form.user_id.data, train=form.train_id.data, time=form.time.data)
  File "<string>", line 4, in __init__
  File "/home/daniel/dke/venv/lib/python3.8/site-packages/sqlalchemy/orm/state.py", line 480, in _initialize_instance
    manager.dispatch.init_failure(self, args, kwargs)
  File "/home/daniel/dke/venv/lib/python3.8/site-packages/sqlalchemy/util/langhelpers.py", line 70, in __exit__
    compat.raise_(
  File "/home/daniel/dke/venv/lib/python3.8/site-packages/sqlalchemy/util/compat.py", line 207, in raise_
    raise exception
  File "/home/daniel/dke/venv/lib/python3.8/site-packages/sqlalchemy/orm/state.py", line 477, in _initialize_instance
    return manager.original_init(*mixed[1:], **kwargs)
  File "/home/daniel/dke/venv/lib/python3.8/site-packages/sqlalchemy/orm/decl_base.py", line 1154, in _declarative_constructor
    raise TypeError(
TypeError: 'user' is an invalid keyword argument for Maintenance
2022-01-17 15:49:08,105 INFO: Microblog startup [in /home/daniel/dke/app/__init__.py:47]
