2022-01-06 14:48:13,374 ERROR: Exception on /train [POST] [in /home/daniel/dke/venv/lib/python3.8/site-packages/flask/app.py:1891]
Traceback (most recent call last):
  File "/home/daniel/dke/venv/lib/python3.8/site-packages/sqlalchemy/engine/base.py", line 1802, in _execute_context
    self.dialect.do_execute(
  File "/home/daniel/dke/venv/lib/python3.8/site-packages/sqlalchemy/engine/default.py", line 719, in do_execute
    cursor.execute(statement, parameters)
sqlite3.InterfaceError: Error binding parameter 0 - probably unsupported type.

The above exception was the direct cause of the following exception:

Traceback (most recent call last):
  File "/home/daniel/dke/venv/lib/python3.8/site-packages/flask/app.py", line 2447, in wsgi_app
    response = self.full_dispatch_request()
  File "/home/daniel/dke/venv/lib/python3.8/site-packages/flask/app.py", line 1952, in full_dispatch_request
    rv = self.handle_user_exception(e)
  File "/home/daniel/dke/venv/lib/python3.8/site-packages/flask/app.py", line 1821, in handle_user_exception
    reraise(exc_type, exc_value, tb)
  File "/home/daniel/dke/venv/lib/python3.8/site-packages/flask/_compat.py", line 39, in reraise
    raise value
  File "/home/daniel/dke/venv/lib/python3.8/site-packages/flask/app.py", line 1950, in full_dispatch_request
    rv = self.dispatch_request()
  File "/home/daniel/dke/venv/lib/python3.8/site-packages/flask/app.py", line 1936, in dispatch_request
    return self.view_functions[rule.endpoint](**req.view_args)
  File "/home/daniel/dke/app/routes.py", line 88, in train
    id = Personwagon.query.get_or_404(form.personwagons.data)
  File "/home/daniel/dke/venv/lib/python3.8/site-packages/flask_sqlalchemy/__init__.py", line 460, in get_or_404
    rv = self.get(ident)
  File "<string>", line 2, in get
  File "/home/daniel/dke/venv/lib/python3.8/site-packages/sqlalchemy/util/deprecations.py", line 401, in warned
    return fn(*args, **kwargs)
  File "/home/daniel/dke/venv/lib/python3.8/site-packages/sqlalchemy/orm/query.py", line 943, in get
    return self._get_impl(ident, loading.load_on_pk_identity)
  File "/home/daniel/dke/venv/lib/python3.8/site-packages/sqlalchemy/orm/query.py", line 947, in _get_impl
    return self.session._get_impl(
  File "/home/daniel/dke/venv/lib/python3.8/site-packages/sqlalchemy/orm/session.py", line 2874, in _get_impl
    return db_load_fn(
  File "/home/daniel/dke/venv/lib/python3.8/site-packages/sqlalchemy/orm/loading.py", line 530, in load_on_pk_identity
    session.execute(
  File "/home/daniel/dke/venv/lib/python3.8/site-packages/sqlalchemy/orm/session.py", line 1689, in execute
    result = conn._execute_20(statement, params or {}, execution_options)
  File "/home/daniel/dke/venv/lib/python3.8/site-packages/sqlalchemy/engine/base.py", line 1614, in _execute_20
    return meth(self, args_10style, kwargs_10style, execution_options)
  File "/home/daniel/dke/venv/lib/python3.8/site-packages/sqlalchemy/sql/elements.py", line 325, in _execute_on_connection
    return connection._execute_clauseelement(
  File "/home/daniel/dke/venv/lib/python3.8/site-packages/sqlalchemy/engine/base.py", line 1481, in _execute_clauseelement
    ret = self._execute_context(
  File "/home/daniel/dke/venv/lib/python3.8/site-packages/sqlalchemy/engine/base.py", line 1845, in _execute_context
    self._handle_dbapi_exception(
  File "/home/daniel/dke/venv/lib/python3.8/site-packages/sqlalchemy/engine/base.py", line 2026, in _handle_dbapi_exception
    util.raise_(
  File "/home/daniel/dke/venv/lib/python3.8/site-packages/sqlalchemy/util/compat.py", line 207, in raise_
    raise exception
  File "/home/daniel/dke/venv/lib/python3.8/site-packages/sqlalchemy/engine/base.py", line 1802, in _execute_context
    self.dialect.do_execute(
  File "/home/daniel/dke/venv/lib/python3.8/site-packages/sqlalchemy/engine/default.py", line 719, in do_execute
    cursor.execute(statement, parameters)
sqlalchemy.exc.InterfaceError: (sqlite3.InterfaceError) Error binding parameter 0 - probably unsupported type.
[SQL: SELECT personwagon.id AS personwagon_id, personwagon.seats AS personwagon_seats, personwagon.max_weight AS personwagon_max_weight, personwagon.width AS personwagon_width, personwagon.train_id_pw AS personwagon_train_id_pw 
FROM personwagon 
WHERE personwagon.id = ?]
[parameters: (<Personwagon 1>,)]
(Background on this error at: https://sqlalche.me/e/14/rvf5)
2022-01-06 14:52:52,603 INFO: Microblog startup [in /home/daniel/dke/app/__init__.py:44]
2022-01-06 15:36:42,318 INFO: Microblog startup [in /home/daniel/dke/app/__init__.py:44]
2022-01-06 15:39:15,770 INFO: Microblog startup [in /home/daniel/dke/app/__init__.py:44]
2022-01-06 15:53:21,341 INFO: Microblog startup [in /home/daniel/dke/app/__init__.py:44]
2022-01-06 15:53:31,673 ERROR: Exception on /train [POST] [in /home/daniel/dke/venv/lib/python3.8/site-packages/flask/app.py:1891]
Traceback (most recent call last):
  File "/home/daniel/dke/venv/lib/python3.8/site-packages/flask/app.py", line 2447, in wsgi_app
    response = self.full_dispatch_request()
  File "/home/daniel/dke/venv/lib/python3.8/site-packages/flask/app.py", line 1952, in full_dispatch_request
    rv = self.handle_user_exception(e)
  File "/home/daniel/dke/venv/lib/python3.8/site-packages/flask/app.py", line 1821, in handle_user_exception
    reraise(exc_type, exc_value, tb)
  File "/home/daniel/dke/venv/lib/python3.8/site-packages/flask/_compat.py", line 39, in reraise
    raise value
  File "/home/daniel/dke/venv/lib/python3.8/site-packages/flask/app.py", line 1950, in full_dispatch_request
    rv = self.dispatch_request()
  File "/home/daniel/dke/venv/lib/python3.8/site-packages/flask/app.py", line 1936, in dispatch_request
    return self.view_functions[rule.endpoint](**req.view_args)
  File "/home/daniel/dke/app/routes.py", line 86, in train
    if form.validate_on_submit():
  File "/home/daniel/dke/venv/lib/python3.8/site-packages/flask_wtf/form.py", line 86, in validate_on_submit
    return self.is_submitted() and self.validate()
  File "/home/daniel/dke/venv/lib/python3.8/site-packages/wtforms/form.py", line 329, in validate
    return super().validate(extra)
  File "/home/daniel/dke/venv/lib/python3.8/site-packages/wtforms/form.py", line 146, in validate
    if not field.validate(self, extra):
  File "/home/daniel/dke/venv/lib/python3.8/site-packages/wtforms/fields/core.py", line 242, in validate
    stop_validation = self._run_validation_chain(form, chain)
  File "/home/daniel/dke/venv/lib/python3.8/site-packages/wtforms/fields/core.py", line 262, in _run_validation_chain
    validator(form, self)
  File "/home/daniel/dke/app/forms.py", line 55, in validate_id
    railwagon = train.railwagon_id
AttributeError: 'NoneType' object has no attribute 'railwagon_id'
2022-01-07 08:01:51,357 INFO: Microblog startup [in /home/daniel/dke/app/__init__.py:44]
2022-01-07 09:24:57,792 INFO: Microblog startup [in /home/daniel/dke/app/__init__.py:44]
